<!-- https://mujoco.readthedocs.io/en/latest/overview.html?highlight=hello.xml#examples -->
<mujoco>
  <option gravity = "0 0 -9.81">
    <flag contact="enable" />
  </option >
   <worldbody>
      <light diffuse="0 0 0" pos="0 0 10" dir="0 0 -1"/>
      <geom type="plane" size="2.25 2.25 0.01" rgba="1 1 1 1"/>
      <body pos="0 0 2.6" euler="0 0 0">
         <joint name="joint0" type="hinge" axis = "0 1 0" pos = "0 0 0.5"/>
         <geom type="cylinder" size="0.02 0.5" mass = "0" rgba="1 1 1 1"/>
         <geom type="sphere" pos = "0 0 -0.5" mass = "1" size="0.1" rgba="1 0 0 1"/>
      </body>
   </worldbody>

   <actuator>
     <motor name="torque" joint="joint0"  gear="1" ctrllimited="true" ctrlrange="-100 100"/>
     <position name="position_servo" joint="joint0" kp="0"/>
     <velocity name="velocity_servo" joint="joint0" kv="0"/>
   </actuator>

</mujoco>
